Traceback (most recent call last):
  File "/home/morgunov/anaconda3/lib/python3.9/site-packages/pyscf/ao2mo/outcore.py", line 324, in general
    async_write(icomp, row0, row1, outbuf)
  File "/home/morgunov/anaconda3/lib/python3.9/site-packages/pyscf/lib/misc.py", line 950, in async_fn
    raise ThreadRuntimeError('Error on thread %s:\n%s'
pyscf.lib.misc.ThreadRuntimeError: Error on thread <pyscf.lib.misc.call_in_background object at 0x7fe9c0318d00>:
[Errno 28] Can't write data (file write failed: time = Mon May  6 01:47:37 2024
, filename = '/tmp/tmp_i1dk6_u', file descriptor = 8, errno = 28, error message = 'No space left on device', buf = 0x55601125c368, total write size = 1536464, bytes this sub-write = 1536464, bytes actually written = 18446744073709551615, offset = 0)

During handling of the above exception, another exception occurred:

Traceback (most recent call last):
  File "/home/morgunov/anaconda3/lib/python3.9/site-packages/pyscf/lib/misc.py", line 968, in __exit__
    handler.result()
  File "/home/morgunov/anaconda3/lib/python3.9/concurrent/futures/_base.py", line 438, in result
    return self.__get_result()
  File "/home/morgunov/anaconda3/lib/python3.9/concurrent/futures/_base.py", line 390, in __get_result
    raise self._exception
  File "/home/morgunov/anaconda3/lib/python3.9/site-packages/pyscf/lib/misc.py", line 948, in async_fn
    handlers[i].result()
  File "/home/morgunov/anaconda3/lib/python3.9/concurrent/futures/_base.py", line 438, in result
    return self.__get_result()
  File "/home/morgunov/anaconda3/lib/python3.9/concurrent/futures/_base.py", line 390, in __get_result
    raise self._exception
  File "/home/morgunov/anaconda3/lib/python3.9/concurrent/futures/thread.py", line 52, in run
    result = self.fn(*self.args, **self.kwargs)
  File "/home/morgunov/anaconda3/lib/python3.9/site-packages/pyscf/ao2mo/outcore.py", line 288, in save
    h5d_eri[row0:row1] = buf[:row1-row0]
  File "h5py/_objects.pyx", line 54, in h5py._objects.with_phil.wrapper
  File "h5py/_objects.pyx", line 55, in h5py._objects.with_phil.wrapper
  File "/home/morgunov/anaconda3/lib/python3.9/site-packages/h5py/_hl/dataset.py", line 920, in __setitem__
    self.id.write(mspace, fspace, val, mtype, dxpl=self._dxpl)
  File "h5py/_objects.pyx", line 54, in h5py._objects.with_phil.wrapper
  File "h5py/_objects.pyx", line 55, in h5py._objects.with_phil.wrapper
  File "h5py/h5d.pyx", line 232, in h5py.h5d.DatasetID.write
  File "h5py/_proxy.pyx", line 114, in h5py._proxy.dset_rw
OSError: [Errno 28] Can't write data (file write failed: time = Mon May  6 01:47:37 2024
, filename = '/tmp/tmp_i1dk6_u', file descriptor = 8, errno = 28, error message = 'No space left on device', buf = 0x55601125c368, total write size = 1536464, bytes this sub-write = 1536464, bytes actually written = 18446744073709551615, offset = 0)

During handling of the above exception, another exception occurred:

Traceback (most recent call last):
  File "/work/morgunov/rev2calcs/run_mom.py", line 416, in <module>
    predictor.run() 
  File "/work/morgunov/rev2calcs/run_mom.py", line 360, in run
    self._do_uccsd(triples=self.doTriples)
  File "/work/morgunov/rev2calcs/run_mom.py", line 276, in _do_uccsd
    self.umf_core.do_ccsd(do_ccsd_t=triples, do_t1_diagn=self.DO_T1_DIAGN, verbose=self.VERBOSITY, frozen=self.freeze_orbs)
  File "/home/morgunov/vv/dmp2/sgscf/uhf.py", line 465, in do_ccsd
    mf.e_corr_ccsd = mcc.kernel(eris=eris, t1=t1, t2=t2)[0]
  File "/home/morgunov/anaconda3/lib/python3.9/site-packages/pyscf/cc/uccsd.py", line 596, in kernel
    return self.ccsd(t1, t2, eris, mbpt2)
  File "/home/morgunov/anaconda3/lib/python3.9/site-packages/pyscf/cc/uccsd.py", line 612, in ccsd
    return ccsd.CCSD.ccsd(self, t1, t2, eris)
  File "/home/morgunov/anaconda3/lib/python3.9/site-packages/pyscf/cc/ccsd.py", line 1088, in ccsd
    eris = self.ao2mo(self.mo_coeff)
  File "/home/morgunov/anaconda3/lib/python3.9/site-packages/pyscf/cc/uccsd.py", line 695, in ao2mo
    return _make_eris_outcore(self, mo_coeff)
  File "/home/morgunov/anaconda3/lib/python3.9/site-packages/pyscf/cc/uccsd.py", line 1178, in _make_eris_outcore
    ao2mo.full(mol, orbvb, eris.feri, dataname='VVVV')
  File "/home/morgunov/anaconda3/lib/python3.9/site-packages/pyscf/ao2mo/__init__.py", line 153, in full
    return mod.full(eri_or_mol, mo_coeff, erifile, dataname, intor,
  File "/home/morgunov/anaconda3/lib/python3.9/site-packages/pyscf/ao2mo/outcore.py", line 110, in full
    general(mol, (mo_coeff,)*4, erifile, dataname,
  File "/home/morgunov/anaconda3/lib/python3.9/site-packages/pyscf/ao2mo/outcore.py", line 330, in general
    ti0 = ti1
  File "/home/morgunov/anaconda3/lib/python3.9/site-packages/pyscf/lib/misc.py", line 970, in __exit__
    raise ThreadRuntimeError('Error on thread %s:\n%s' % (self, e))
pyscf.lib.misc.ThreadRuntimeError: Error on thread <pyscf.lib.misc.call_in_background object at 0x7fe9c0318d00>:
[Errno 28] Can't write data (file write failed: time = Mon May  6 01:47:37 2024
, filename = '/tmp/tmp_i1dk6_u', file descriptor = 8, errno = 28, error message = 'No space left on device', buf = 0x55601125c368, total write size = 1536464, bytes this sub-write = 1536464, bytes actually written = 18446744073709551615, offset = 0)
Exception ignored in: <function H5TmpFile.__del__ at 0x7fe9ce0738b0>
Traceback (most recent call last):
  File "/home/morgunov/anaconda3/lib/python3.9/site-packages/pyscf/lib/misc.py", line 1004, in __del__
  File "/home/morgunov/anaconda3/lib/python3.9/site-packages/h5py/_hl/files.py", line 466, in close
  File "h5py/_objects.pyx", line 54, in h5py._objects.with_phil.wrapper
  File "h5py/_objects.pyx", line 55, in h5py._objects.with_phil.wrapper
  File "h5py/h5f.pyx", line 352, in h5py.h5f.FileID._close_open_objects
RuntimeError: Dirty entry flush destroy failed (file write failed: time = Mon May  6 01:47:45 2024
, filename = '/tmp/tmp_i1dk6_u', file descriptor = 8, errno = 28, error message = 'No space left on device', buf = 0x7fe91c9f6f00, total write size = 4224, bytes this sub-write = 4224, bytes actually written = 18446744073709551615, offset = 0)
